<?xml version="1.0"?>
<robot xmlns:xacro="http://www.ros.org/wiki/xacro" name="gripper_robot">

    <!-- 定义宏 -->
    <xacro:macro name="gripper" params="parent_link">

        <!-- gripper关节上下限 -->
        <xacro:property name="joint_lower_bound" value="-0.8" />
        <xacro:property name="joint_upper_bound" value="0.6" />

        <!-- camera_connect -->
        <link name="camera_connect">
            <inertial>
                <origin xyz="0.045819 0 0.0039533" rpy="0 0 0" />
                <mass value="0.051365" />
                <inertia ixx="1.5947E-05" ixy="2.2017E-20" ixz="-1.4477E-07" iyy="8.6653E-05" iyz="-1.9465E-21" izz="0.00010204" />
            </inertial>
            <visual>
                <origin xyz="0 0 0" rpy="0 0 0" />
                <geometry>
                    <mesh filename="package://inspire_description/meshes/camera_connect.STL" />
                </geometry>
                <material name="">
                    <color rgba="0.79216 0.81961 0.93333 1" />
                </material>
            </visual>
            <collision>
                <origin xyz="0 0 0" rpy="0 0 0" />
                <geometry>
                    <mesh filename="package://inspire_description/meshes/camera_connect.STL" />
                </geometry>
            </collision>
        </link>
        
        <joint name="arm_joint_camera_connect" type="fixed">
            <origin xyz="0 0 0" rpy="0 0 0" />
            <parent link="${parent_link}" />
            <child link="camera_connect" />
        </joint>

        <!-- gripper -->
        <link name="gripper_base_link">
            <inertial>
                <origin xyz="-2.6792E-06 1.4343E-05 -0.040955" rpy="0 0 0" />
                <mass value="0.075349" />
                <inertia ixx="6.9695E-05" ixy="-2.8955E-12" ixz="1.2653E-08" iyy="6.0426E-05" iyz="2.2585E-08" izz="1.9195E-05" />
            </inertial>
            <visual>
                <origin xyz="0 0 0" rpy="0 0 0" />
                <geometry>
                    <mesh filename="package://inspire_description/meshes/gripper_base_link.STL" />
                </geometry>
                <material name="">
                    <color rgba="0.79216 0.81961 0.93333 1" />
                </material>
            </visual>
            <collision>
                <origin xyz="0 0 0" rpy="0 0 0" />
                <geometry>
                    <mesh filename="package://inspire_description/meshes/gripper_base_link.STL" />
                </geometry>
            </collision>
        </link>
        
        <joint name="arm_joint_gripper" type="fixed">
            <origin xyz="0 0 0.008" rpy="0 0 0" />
            <parent link="camera_connect" />
            <child link="gripper_base_link" />
        </joint>
        
        <link name="gripper_Link1">
            <inertial>
                <origin xyz="0.0001 0.0085832 0.013664" rpy="0 0 0" />
                <mass value="0.0024857" />
                <inertia ixx="5.8907E-07" ixy="1.3343E-19" ixz="4.2984E-19" iyy="5.2237E-07" iyz="-2.5787E-07" izz="2.7386E-07" />
            </inertial>
            <visual>
                <origin xyz="0 0 0" rpy="0 0 0" />
                <geometry>
                    <mesh filename="package://inspire_description/meshes/gripper_Link1.STL" />
                </geometry>
                <material name="">
                    <color rgba="0.79216 0.81961 0.93333 1" />
                </material>
            </visual>
            <collision>
                <origin xyz="0 0 0" rpy="0 0 0" />
                <geometry>
                    <mesh filename="package://inspire_description/meshes/gripper_Link1.STL" />
                </geometry>
            </collision>
        </link>
        
        <joint name="gripper_joint1" type="revolute">
            <origin xyz="0 -0.04 0.09" rpy="0.8663 0 0" />
            <parent link="gripper_base_link" />
            <child link="gripper_Link1" />
            <axis xyz="1 0 0" />
            <limit lower="${joint_lower_bound}" upper="${joint_upper_bound}" effort="100" velocity="1" />
        </joint>
        
        <link name="gripper_Link2">
            <inertial>
                <origin xyz="9.9997E-05 0.011846 0.011367" rpy="0 0 0" />
                <mass value="0.0044927" />
                <inertia ixx="4.099E-07" ixy="-7.8736E-14" ixz="-7.8248E-14" iyy="4.2946E-07" iyz="-3.8654E-08" izz="1.6162E-07" />
            </inertial>
            <visual>
                <origin xyz="0 0 0" rpy="0 0 0" />
                <geometry>
                    <mesh filename="package://inspire_description/meshes/gripper_Link2.STL" />
                </geometry>
                <material name="">
                    <color rgba="0.79216 0.81961 0.93333 1" />
                </material>
            </visual>
            <collision>
                <origin xyz="0 0 0" rpy="0 0 0" />
                <geometry>
                    <mesh filename="package://inspire_description/meshes/gripper_Link2.STL" />
                </geometry>
            </collision>
        </link>
        
        <joint name="gripper_joint2" type="revolute">
            <origin xyz="0 0.022341 0.035565" rpy="-0.8663 0 0" />
            <parent link="gripper_Link1" />
            <child link="gripper_Link2" />
            <axis xyz="-1 0 0" />
            <limit lower="${joint_lower_bound}" upper="${joint_upper_bound}" effort="100" velocity="1" />
        </joint>
        
        <link name="gripper_Link3">
            <inertial>
                <origin xyz="0.0001 -0.0085832 0.013664" rpy="0 0 0" />
                <mass value="0.0024857" />
                <inertia ixx="5.8907E-07" ixy="-3.3324E-19" ixz="3.1193E-19" iyy="5.2237E-07" iyz="2.5787E-07" izz="2.7386E-07" />
            </inertial>
            <visual>
                <origin xyz="0 0 0" rpy="0 0 0" />
                <geometry>
                    <mesh filename="package://inspire_description/meshes/gripper_Link3.STL" />
                </geometry>
                <material name="">
                    <color rgba="0.79216 0.81961 0.93333 1" />
                </material>
            </visual>
            <collision>
                <origin xyz="0 0 0" rpy="0 0 0" />
                <geometry>
                    <mesh filename="package://inspire_description/meshes/gripper_Link3.STL" />
                </geometry>
            </collision>
        </link>
        
        <joint name="gripper_joint3" type="revolute">
            <origin xyz="0 0.04 0.09" rpy="-0.8663 0 0" />
            <parent link="gripper_base_link" />
            <child link="gripper_Link3" />
            <axis xyz="-1 0 0" />
            <limit lower="${joint_lower_bound}" upper="${joint_upper_bound}" effort="100" velocity="1" />
        </joint>
        
        <link name="gripper_Link4">
            <inertial>
                <origin xyz="9.9999E-05 -0.011846 0.011367" rpy="0 0 0" />
                <mass value="0.0044926" />
                <inertia ixx="4.099E-07" ixy="-1.4237E-13" ixz="-2.483E-13" iyy="4.2946E-07" iyz="3.8655E-08" izz="1.6162E-07" />
            </inertial>
            <visual>
                <origin xyz="0 0 0" rpy="0 0 0" />
                <geometry>
                    <mesh filename="package://inspire_description/meshes/gripper_Link4.STL" />
                </geometry>
                <material name="">
                    <color rgba="0.79216 0.81961 0.93333 1" />
                </material>
            </visual>
            <collision>
                <origin xyz="0 0 0" rpy="0 0 0" />
                <geometry>
                    <mesh filename="package://inspire_description/meshes/gripper_Link4.STL" />
                </geometry>
            </collision>
        </link>
        
        <joint name="gripper_joint4" type="revolute">
            <origin xyz="0 -0.022341 0.035565" rpy="0.8663 0 0" />
            <parent link="gripper_Link3" />
            <child link="gripper_Link4" />
            <axis xyz="1 0 0" />
            <limit lower="${joint_lower_bound}" upper="${joint_upper_bound}" effort="100" velocity="1" />
        </joint>
        
        <!-- gripper tip virtual link -->
        <link name="gripper_tip_link"/>
        
        <joint name="gripper_tip_joint" type="fixed">
            <origin xyz="0 0 0.1522" rpy="0 0 0" />
            <parent link="${parent_link}" />
            <child link="gripper_tip_link" />
        </joint>
    </xacro:macro>

</robot>
